<?xml version="1.0" encoding="utf-8"?>
<!-- =================================================================================== -->
<!-- |    This document was autogenerated by xacro from /home/admin-skurz/git/uni/ARPG/artus/scripts/../ros_ws/src/simulation/gazebo/racer_description/urdf/racer.xacro | -->
<!-- |    EDITING THIS FILE BY HAND IS NOT RECOMMENDED                                 | -->
<!-- =================================================================================== -->
<robot name="myrobot">
  <link name="base_link"/>
  <joint name="base_link_joint" type="fixed">
    <origin rpy="0 0 0" xyz="0 0 0.05"/>
    <parent link="base_link"/>
    <child link="chassis"/>
  </joint>
  <!--  Body  -->
  <link name="chassis">
    <inertial>
      <mass value="3.5"/>
      <origin rpy=" 0 0 0" xyz="0 0 0.0225"/>
      <inertia ixx="0.0123666666667" ixy="0" ixz="0" iyy="0.0729458333333" iyz="0" izz="0.0794791666667"/>
    </inertial>
    <collision name="collision">
      <origin rpy=" 0 0 0" xyz="0 0 0.0225"/>
      <geometry>
        <box size="0.49 0.18 0.1"/>
      </geometry>
    </collision>
    <visual>
      <origin rpy=" 0 0 0" xyz="0 0 0"/>
      <geometry>
        <mesh filename="package://racer_description/meshes/car.dae"/>
      </geometry>
    </visual>
  </link>
  <joint name="base_body_joint" type="fixed">
    <origin rpy="0 0 0" xyz="0 0 0"/>
    <parent link="base_link"/>
    <child link="body"/>
  </joint>
  <link name="body">
    <visual>
      <origin rpy=" 0 0 0" xyz="0 0 0.05"/>
      <geometry>
        <mesh filename="package://racer_description/meshes/body.dae"/>
      </geometry>
    </visual>
  </link>
  <link name="left_wheel_front">
    <inertial>
      <mass value="0.2"/>
      <origin rpy="1.57079632679 0 0" xyz="0 0.02 0"/>
      <inertia ixx="0.00015875" ixy="0" ixz="0" iyy="0.00015875" iyz="0" izz="0.00025"/>
    </inertial>
    <collision>
      <origin rpy="1.57079632679 0 0 " xyz="0 0.02 0"/>
      <geometry>
        <cylinder length="0.045" radius="0.05"/>
      </geometry>
    </collision>
    <visual>
      <origin rpy="0 0 3.14159265359" xyz="0 0.02 0"/>
      <geometry>
        <mesh filename="package://racer_description/meshes/wheel.dae"/>
      </geometry>
    </visual>
  </link>
  <joint name="left_wheel_front_hinge" type="continuous">
    <parent link="left_steering"/>
    <child link="left_wheel_front"/>
    <origin rpy="0 0 0" xyz="0.0 0.001 0"/>
    <axis rpy="0 0 0" xyz="0 1 0"/>
    <limit effort="20" velocity="500"/>
    <joint_properties damping="0.0" friction="0.0"/>
  </joint>
  <transmission name="left_wheel_front_transmission" type="SimpleTransmission">
    <type>transmission_interface/SimpleTransmission</type>
    <joint name="left_wheel_front_hinge">
      <hardwareInterface>hardware_interface/EffortJointInterface</hardwareInterface>
    </joint>
    <actuator name="left_wheel_front_motor">
      <hardwareInterface>hardware_interface/EffortJointInterface</hardwareInterface>
      <mechanicalReduction>1</mechanicalReduction>
    </actuator>
  </transmission>
  <gazebo reference="left_wheel_front">
    <mu1>1.2</mu1>
    <mu2>1.2</mu2>
  </gazebo>
  <link name="right_wheel_front">
    <inertial>
      <mass value="0.2"/>
      <origin rpy="1.57079632679 0 0" xyz="0 -0.02 0"/>
      <inertia ixx="0.00015875" ixy="0" ixz="0" iyy="0.00015875" iyz="0" izz="0.00025"/>
    </inertial>
    <collision>
      <origin rpy="1.57079632679 0 0 " xyz="0 -0.02 0"/>
      <geometry>
        <cylinder length="0.045" radius="0.05"/>
      </geometry>
    </collision>
    <visual>
      <origin rpy="0 0 0.0" xyz="0 -0.02 0"/>
      <geometry>
        <mesh filename="package://racer_description/meshes/wheel.dae"/>
      </geometry>
    </visual>
  </link>
  <joint name="right_wheel_front_hinge" type="continuous">
    <parent link="right_steering"/>
    <child link="right_wheel_front"/>
    <origin rpy="0 0 0" xyz="0.0 -0.001 0"/>
    <axis rpy="0 0 0" xyz="0 1 0"/>
    <limit effort="20" velocity="500"/>
    <joint_properties damping="0.0" friction="0.0"/>
  </joint>
  <transmission name="right_wheel_front_transmission" type="SimpleTransmission">
    <type>transmission_interface/SimpleTransmission</type>
    <joint name="right_wheel_front_hinge">
      <hardwareInterface>hardware_interface/EffortJointInterface</hardwareInterface>
    </joint>
    <actuator name="right_wheel_front_motor">
      <hardwareInterface>hardware_interface/EffortJointInterface</hardwareInterface>
      <mechanicalReduction>1</mechanicalReduction>
    </actuator>
  </transmission>
  <gazebo reference="right_wheel_front">
    <mu1>1.2</mu1>
    <mu2>1.2</mu2>
  </gazebo>
  <link name="left_wheel_back">
    <inertial>
      <mass value="0.2"/>
      <origin rpy="1.57079632679 0 0" xyz="0 0.021 0"/>
      <inertia ixx="0.00015875" ixy="0" ixz="0" iyy="0.00015875" iyz="0" izz="0.00025"/>
    </inertial>
    <collision>
      <origin rpy="1.57079632679 0 0 " xyz="0 0.021 0"/>
      <geometry>
        <cylinder length="0.045" radius="0.05"/>
      </geometry>
    </collision>
    <visual>
      <origin rpy="0 0 3.14159265359" xyz="0 0.021 0"/>
      <geometry>
        <mesh filename="package://racer_description/meshes/wheel.dae"/>
      </geometry>
    </visual>
  </link>
  <joint name="left_wheel_back_hinge" type="continuous">
    <parent link="chassis"/>
    <child link="left_wheel_back"/>
    <origin rpy="0 0 0" xyz="-0.16 0.1055 0"/>
    <axis rpy="0 0 0" xyz="0 1 0"/>
    <limit effort="20" velocity="500"/>
    <joint_properties damping="0.0" friction="0.0"/>
  </joint>
  <transmission name="left_wheel_back_transmission" type="SimpleTransmission">
    <type>transmission_interface/SimpleTransmission</type>
    <joint name="left_wheel_back_hinge">
      <hardwareInterface>hardware_interface/EffortJointInterface</hardwareInterface>
    </joint>
    <actuator name="left_wheel_back_motor">
      <hardwareInterface>hardware_interface/EffortJointInterface</hardwareInterface>
      <mechanicalReduction>1</mechanicalReduction>
    </actuator>
  </transmission>
  <gazebo reference="left_wheel_back">
    <mu1>1.2</mu1>
    <mu2>1.2</mu2>
  </gazebo>
  <link name="right_wheel_back">
    <inertial>
      <mass value="0.2"/>
      <origin rpy="1.57079632679 0 0" xyz="0 -0.021 0"/>
      <inertia ixx="0.00015875" ixy="0" ixz="0" iyy="0.00015875" iyz="0" izz="0.00025"/>
    </inertial>
    <collision>
      <origin rpy="1.57079632679 0 0 " xyz="0 -0.021 0"/>
      <geometry>
        <cylinder length="0.045" radius="0.05"/>
      </geometry>
    </collision>
    <visual>
      <origin rpy="0 0 0.0" xyz="0 -0.021 0"/>
      <geometry>
        <mesh filename="package://racer_description/meshes/wheel.dae"/>
      </geometry>
    </visual>
  </link>
  <joint name="right_wheel_back_hinge" type="continuous">
    <parent link="chassis"/>
    <child link="right_wheel_back"/>
    <origin rpy="0 0 0" xyz="-0.16 -0.1055 0"/>
    <axis rpy="0 0 0" xyz="0 1 0"/>
    <limit effort="20" velocity="500"/>
    <joint_properties damping="0.0" friction="0.0"/>
  </joint>
  <transmission name="right_wheel_back_transmission" type="SimpleTransmission">
    <type>transmission_interface/SimpleTransmission</type>
    <joint name="right_wheel_back_hinge">
      <hardwareInterface>hardware_interface/EffortJointInterface</hardwareInterface>
    </joint>
    <actuator name="right_wheel_back_motor">
      <hardwareInterface>hardware_interface/EffortJointInterface</hardwareInterface>
      <mechanicalReduction>1</mechanicalReduction>
    </actuator>
  </transmission>
  <gazebo reference="right_wheel_back">
    <mu1>1.2</mu1>
    <mu2>1.2</mu2>
  </gazebo>
  <link name="left_steering">
    <inertial>
      <mass value="0.07"/>
      <origin rpy="0 0 0" xyz="0 0 0"/>
      <inertia ixx="4.66666666667e-06" ixy="0" ixz="0" iyy="4.66666666667e-06" iyz="0" izz="4.66666666667e-06"/>
    </inertial>
    <visual>
      <origin rpy="0 0 0" xyz="0 0 0"/>
      <geometry>
        <sphere radius="0.01"/>
      </geometry>
    </visual>
  </link>
  <gazebo reference="left_steering">
    <material>Gazebo/Grey</material>
  </gazebo>
  <joint name="left_steering_hinge" type="revolute">
    <origin rpy="0 0 0" xyz="0.16 0.1055 0"/>
    <parent link="chassis"/>
    <child link="left_steering"/>
    <axis xyz="0 0 1"/>
    <limit effort="10" lower="-1.0" upper="1.0" velocity="100"/>
  </joint>
  <transmission name="left_steering_hinge_transmission" type="SimpleTransmission">
    <type>transmission_interface/SimpleTransmission</type>
    <joint name="left_steering_hinge">
      <hardwareInterface>hardware_interface/EffortJointInterface</hardwareInterface>
    </joint>
    <actuator name="left_steering_hinge_motor">
      <hardwareInterface>hardware_interface/EffortJointInterface</hardwareInterface>
      <mechanicalReduction>1</mechanicalReduction>
    </actuator>
  </transmission>
  <link name="right_steering">
    <inertial>
      <mass value="0.07"/>
      <origin rpy="0 0 0" xyz="0 0 0"/>
      <inertia ixx="4.66666666667e-06" ixy="0" ixz="0" iyy="4.66666666667e-06" iyz="0" izz="4.66666666667e-06"/>
    </inertial>
    <visual>
      <origin rpy="0 0 0" xyz="0 0 0"/>
      <geometry>
        <sphere radius="0.01"/>
      </geometry>
    </visual>
  </link>
  <gazebo reference="right_steering">
    <material>Gazebo/Grey</material>
  </gazebo>
  <joint name="right_steering_hinge" type="revolute">
    <origin rpy="0 0 0" xyz="0.16 -0.1055 0"/>
    <parent link="chassis"/>
    <child link="right_steering"/>
    <axis xyz="0 0 1"/>
    <limit effort="10" lower="-1.0" upper="1.0" velocity="100"/>
  </joint>
  <transmission name="right_steering_hinge_transmission" type="SimpleTransmission">
    <type>transmission_interface/SimpleTransmission</type>
    <joint name="right_steering_hinge">
      <hardwareInterface>hardware_interface/EffortJointInterface</hardwareInterface>
    </joint>
    <actuator name="right_steering_hinge_motor">
      <hardwareInterface>hardware_interface/EffortJointInterface</hardwareInterface>
      <mechanicalReduction>1</mechanicalReduction>
    </actuator>
  </transmission>
  <!-- Camera -->
  <link name="camera">
    <inertial>
      <mass value="0.1"/>
      <origin rpy="0 0 0" xyz="0 0 0.0225"/>
      <inertia ixx="0.000248333333333" ixy="0" ixz="0" iyy="0.000248333333333" iyz="0" izz="1.5e-05"/>
    </inertial>
    <collision>
      <origin rpy="0 0 0" xyz="0 0 0"/>
      <geometry>
        <box size="0.03 0.17 0.03"/>
      </geometry>
    </collision>
    <visual>
      <origin rpy="0 0 0" xyz="0.260 0 -0.0125"/>
      <geometry>
        <mesh filename="package://racer_description/meshes/ZED.dae"/>
      </geometry>
    </visual>
  </link>
  <joint name="camera_joint" type="fixed">
    <axis xyz="0 1 0"/>
    <origin rpy="0 0 0" xyz="0.01 0 0.0"/>
    <parent link="chassis"/>
    <child link="camera"/>
  </joint>
  <!-- Hokuyo Laser -->
  <link name="laser">
    <inertial>
      <mass value="0.1"/>
      <origin rpy="0 0 0" xyz="0 0 0.0225"/>
      <inertia ixx="0.000166666666667" ixy="0" ixz="0" iyy="0.000166666666667" iyz="0" izz="0.000166666666667"/>
    </inertial>
    <collision>
      <origin rpy="0 0 0" xyz="0 0 0.0225"/>
      <geometry>
        <box size="0.1 0.1 0.1"/>
      </geometry>
    </collision>
    <visual>
      <!--<origin xyz="0 0 ${wheel_height/2}" rpy="0 0 0"/>-->
      <origin rpy="0 0 0" xyz="0 0 -0.02"/>
      <geometry>
        <mesh filename="package://racer_description/meshes/hokuyo.dae"/>
      </geometry>
    </visual>
  </link>
  <joint name="laser_joint" type="fixed">
    <axis xyz="0 1 0"/>
    <origin rpy="0 0 0" xyz="0.21 0 0.135"/>
    <parent link="chassis"/>
    <child link="laser"/>
  </joint>
  <!-- IMU -->
  <link name="imu_link"/>
  <joint name="imu_joint" type="fixed">
    <axis xyz="0 1 0"/>
    <origin rpy="0 0 0" xyz="0 0 0.135"/>
    <parent link="chassis"/>
    <child link="imu_link"/>
  </joint>
</robot>
